Workbook

Sheet proforma
D4: FACTURA PROFORMA:
D5: PROFORMA: 291225462RNM
D6: FECHA:26/12/2025
B8: Datos del Cliente:
B9: Nombre: | D9: C.I.F:
B10: Dirección: | D10: C.P.:
B11: Ciudad: | D11: Provincia:
B12: Pais: | D12: Telf:
B13: Contacto: | D13: e -mail:
B15: Detalle de Conceptos:
B16: RESINAS 3D
B17: DENOMINACION | D17: Cant.Unit | E17: Precio €/U | F17: Total €
F18: =IF(D18<>"",D18*E18,"")
F36: =IF(D36<>"",D36*E36,"")
F37: =IF(D37<>"",D37*E37,"")
F38: =IF(D38<>"",D38*E38,"")
F39: =IF(D39<>"",D39*E39,"")
F40: =IF(D40<>"",D40*E40,"")
F41: =IF(D41<>"",D41*E41,"")
B42: SUB TOTAL BASE IMPONIBLE | F42: =SUM(F18:F41) -> 0
B43: Descuento % | C43: ESPECIAL | D43: 50 | F43: =F42*(D43/100)*(-1) -> 0
B44: TOTAL BASE IMPONIBLE PINTURAS | F44: =SUM(F42:F43) -> 0
B45: Portes Península | C45: Portes Minimos | D45: 1 | E45: 17 | F45: =D45*E45 -> 17
B46: MANO DE OBRA | F46: =IF(D46<>"",(D46*E46),"")
B47: Otros Varios | F47: =IF(D47<>"",(D47*E47),"")
B48: TOTAL BASE IMPONIBLE | F48: =SUM(F44:F47) -> 17
B49: 21% IVA | F49: =F48*0.21 -> 3.57
B50: TOTAL FACTURA: | F50: =SUM(F48:F49) -> 20.57
B53: Condiciones de Pago:
B55: Forma de Pago: | C55: Transferencia
B56: Banco/NºCta: | C56: Banco Sabadell IBAN: ES14 0081 0286 8800 0184 3288
B57: Forma de Envio: | C57: portes pagados
B58: Vencimiento:
B60: NCHEMICALS RESINAS Y PINTURAS S.L.U.
B61: C/Cantueso 44 | F61: TF:+34 633 48 00 92
B62: 03600 ELDA (ALICANTE) – ESPAÑA | F62: E-mail: hola@nchemicals.es
B63: C.I.F.: B16885279 | F63: suelosderesina@gmail.com

Sheet pedido
E4: PEDIDO:
E5: =proforma!D5 -> PROFORMA: 291225462RNM
E6: =proforma!D6 -> FECHA:26/12/2025
J7: RELLENAR ENCIMA SI LA DIRECCION DE ENVIO ES DIFERENTE A LA DIRECCION DEL CLIENTE
B8: Datos del Cliente: | J8: Datos del Envio:
B9: Nombre: | C9: =IF(proforma!C9<>"",(proforma!C9),"") | D9: C.I.F: | E9: =IF(proforma!E9<>"",(proforma!E9),"") | J9: Nombre: | K9: =IF(proforma!C9<>"",(proforma!C9),"") | L9: C.I.F: | M9: =IF(proforma!E9<>"",(proforma!E9),"")
B10: Dirección: | C10: =IF(proforma!C10<>"",(proforma!C10),"") | D10: C.P.: | E10: =IF(proforma!E10<>"",(proforma!E10),"") | J10: Nombre: | K10: =IF(proforma!C10<>"",(proforma!C10),"") | L10: C.P.: | M10: =IF(proforma!E10<>"",(proforma!E10),"")
B11: Ciudad: | C11: =IF(proforma!C11<>"",(proforma!C11),"") | D11: Provincia: | E11: =IF(proforma!E11<>"",(proforma!E11),"") | J11: Nombre: | K11: =IF(proforma!C11<>"",(proforma!C11),"") | L11: Provincia: | M11: =IF(proforma!E11<>"",(proforma!E11),"")
B12: Pais: | C12: =IF(proforma!C12<>"",(proforma!C12),"") | D12: Telf: | E12: =IF(proforma!E12<>"",(proforma!E12),"") | J12: Nombre: | K12: =IF(proforma!C12<>"",(proforma!C12),"") | L12: Telf: | M12: =IF(proforma!E12<>"",(proforma!E12),"")
B13: Contacto: | C13: =IF(proforma!C13<>"",(proforma!C13),"") | D13: e -mail: | E13: =IF(proforma!E13<>"",(proforma!E13),"") | J13: Nombre: | K13: =IF(proforma!C13<>"",(proforma!C13),"") | L13: e -mail: | M13: =IF(proforma!E13<>"",(proforma!E13),"")
E14: =IF(proforma!E14<>"",(proforma!E14),"") | J14: Nombre:
B15: Detalle de Conceptos: | J15: PESO NETO:
J16: PESO BRUTO :
B17: DENOMINACION | D17: Cant.Unit | E17: Precio €/U | F17: Total € | J17: TOTAL BULTOS:
F18: =IF(D18<>"",D18*E18,"") | J18: Nombre:
B19: =IF(proforma!B19<>"",(proforma!B19),"") | C19: =IF(proforma!C19<>"",(proforma!C19),"") | D19: =IF(proforma!D17<>"",(proforma!D17),"") -> Cant.Unit | E19: =IF(proforma!E17<>"",(proforma!E17),"") -> Precio €/U | J19: PORTES: | K19: PAGADOS
B20: =IF(proforma!B20<>"",(proforma!B20),"") | C20: =IF(proforma!C20<>"",(proforma!C20),"") | D20: =IF(proforma!D20<>"",(proforma!D20),"")
B21: =IF(proforma!B21<>"",(proforma!B21),"") | C21: =IF(proforma!C21<>"",(proforma!C21),"") | D21: =IF(proforma!D21<>"",(proforma!D21),"")
B22: =IF(proforma!B22<>"",(proforma!B22),"") | C22: =IF(proforma!C22<>"",(proforma!C22),"") | D22: =IF(proforma!D22<>"",(proforma!D22),"")
B23: =IF(proforma!B23<>"",(proforma!B23),"") | C23: =IF(proforma!C23<>"",(proforma!C23),"") | D23: =IF(proforma!D23<>"",(proforma!D23),"")
B24: =IF(proforma!B24<>"",(proforma!B24),"") | C24: =IF(proforma!C24<>"",(proforma!C24),"") | D24: =IF(proforma!D24<>"",(proforma!D24),"")
B25: =IF(proforma!B25<>"",(proforma!B25),"") | C25: =IF(proforma!C25<>"",(proforma!C25),"") | D25: =IF(proforma!D25<>"",(proforma!D25),"")
B26: =IF(proforma!B26<>"",(proforma!B26),"") | C26: =IF(proforma!C26<>"",(proforma!C26),"") | D26: =IF(proforma!D26<>"",(proforma!D26),"")
B27: =IF(proforma!B27<>"",(proforma!B27),"") | C27: =IF(proforma!C27<>"",(proforma!C27),"") | D27: =IF(proforma!D27<>"",(proforma!D27),"")
B28: =IF(proforma!B28<>"",(proforma!B28),"") | C28: =IF(proforma!C28<>"",(proforma!C28),"") | D28: =IF(proforma!D28<>"",(proforma!D28),"")
B29: =IF(proforma!B29<>"",(proforma!B29),"") | C29: =IF(proforma!C29<>"",(proforma!C29),"") | D29: =IF(proforma!D29<>"",(proforma!D29),"")
B30: =IF(proforma!B30<>"",(proforma!B30),"") | C30: =IF(proforma!C30<>"",(proforma!C30),"") | D30: =IF(proforma!D30<>"",(proforma!D30),"")
B31: =IF(proforma!B31<>"",(proforma!B31),"") | C31: =IF(proforma!C31<>"",(proforma!C31),"") | D31: =IF(proforma!D31<>"",(proforma!D31),"")
... B34: =IF(proforma!B34<>"",(proforma!B34),"") | C34: =IF(proforma!C34<>"",(proforma!C34),"") | D34: =IF(proforma!D34<>"",(proforma!D34),"")
B35: =IF(proforma!B35<>"",(proforma!B35),"") | C35: =IF(proforma!C35<>"",(proforma!C35),"") | D35: =IF(proforma!D35<>"",(proforma!D35),"") | E35: =IF(proforma!E33<>"",(proforma!E33),"")
B36: =IF(proforma!B36<>"",(proforma!B36),"") | C36: =IF(proforma!C36<>"",(proforma!C36),"") | D36: =IF(proforma!D36<>"",(proforma!D36),"") | E36: =IF(proforma!E34<>"",(proforma!E34),"")
B37: =IF(proforma!B37<>"",(proforma!B37),"") | C37: =IF(proforma!C37<>"",(proforma!C37),"") | D37: =IF(proforma!D37<>"",(proforma!D37),"") | E37: =IF(proforma!E35<>"",(proforma!E35),"")
B38: =IF(proforma!B38<>"",(proforma!B38),"") | C38: =IF(proforma!C38<>"",(proforma!C38),"") | D38: =IF(proforma!D38<>"",(proforma!D38),"") | E38: =IF(proforma!E36<>"",(proforma!E36),"")
B39: =IF(proforma!B39<>"",(proforma!B39),"") | C39: =IF(proforma!C39<>"",(proforma!C39),"") | D39: =IF(proforma!D39<>"",(proforma!D39),"") | E39: =IF(proforma!E37<>"",(proforma!E37),"")
B40: =IF(proforma!B40<>"",(proforma!B40),"") | C40: =IF(proforma!C40<>"",(proforma!C40),"") | D40: =IF(proforma!D40<>"",(proforma!D40),"") | E40: =IF(proforma!E38<>"",(proforma!E38),"")
B41: =IF(proforma!B41<>"",(proforma!B41),"") | E41: =IF(proforma!E39<>"",(proforma!E39),"")
B42: =IF(proforma!B42<>"",(proforma!B42),"") -> SUB TOTAL BASE IMPONIBLE | C42: =IF(proforma!C40<>"",(proforma!C40),"") | D42: =IF(proforma!D40<>"",(proforma!D40),"") | E42: =IF(proforma!E40<>"",(proforma!E40),"") | F42: =IF(D42<>"",D42*E42,"")
B43: =IF(proforma!B41<>"",(proforma!B41),"") | C43: =IF(proforma!C41<>"",(proforma!C41),"") | D43: =IF(proforma!D41<>"",(proforma!D41),"") | E43: =IF(proforma!E41<>"",(proforma!E41),"") | F43: =IF(D43<>"",D43*E43,"")
B44: SUB TOTAL BASE IMPONIBLE | F44: =SUM(F18:F43) -> 0
B45: =proforma!B43 -> Descuento % | D45: =proforma!D43 -> 50 | F45: =proforma!F43 -> 0
...

Sheet albaran
E4: ALBARAN ENTREGA:
E5: =proforma!D5 -> PROFORMA: 291225462RNM
E6: =proforma!D6 -> FECHA:26/12/2025
B8: Datos del Cliente:
B9: Nombre: | C9: =IF(proforma!C9<>"",(proforma!C9),"") | D9: C.I.F: | E9: =IF(proforma!E9<>"",(proforma!E9),"")
B10: Dirección: | D10: C.P.: | E10: =IF(proforma!E10<>"",(proforma!E10),"")
B11: Ciudad: | D11: Provincia: | E11: =IF(proforma!E11<>"",(proforma!E11),"")
B12: Pais: | D12: Telf: | E12: =IF(proforma!E12<>"",(proforma!E12),"")
B13: Contacto: | C13: =IF(proforma!C13<>"",(proforma!C13),"") | D13: e -mail: | E13: =IF(proforma!E13<>"",(proforma!E13),"")
E14: =IF(proforma!E14<>"",(proforma!E14),"")
B15: Detalle de Conceptos:
B17: DENOMINACION | D17: Cant.Unit | E17: Precio €/U | F17: Total €
F18: =IF(D18<>"",D18*E18,"")
B19: =IF(proforma!B19<>"",(proforma!B19),"") | C19: =IF(proforma!C19<>"",(proforma!C19),"") | D19: =IF(proforma!D19<>"",(proforma!D19),"")
B20: =IF(proforma!B20<>"",(proforma!B20),"") | C20: =IF(proforma!C20<>"",(proforma!C20),"") | D20: =IF(proforma!D20<>"",(proforma!D20),"")
B21: =IF(proforma!B21<>"",(proforma!B21),"") | C21: =IF(proforma!C21<>"",(proforma!C21),"") | D21: =IF(proforma!D21<>"",(proforma!D21),"")
B22: =IF(proforma!B22<>"",(proforma!B22),"") | C22: =IF(proforma!C22<>"",(proforma!C22),"") | D22: =IF(proforma!D22<>"",(proforma!D22),"")
B23: =IF(proforma!B23<>"",(proforma!B23),"") | C23: =IF(proforma!C23<>"",(proforma!C23),"") | D23: =IF(proforma!D23<>"",(proforma!D23),"")
B24: =IF(proforma!B24<>"",(proforma!B24),"") | C24: =IF(proforma!C24<>"",(proforma!C24),"") | D24: =IF(proforma!D24<>"",(proforma!D24),"")
B25: =IF(proforma!B25<>"",(proforma!B25),"") | C25: =IF(proforma!C25<>"",(proforma!C25),"") | D25: =IF(proforma!D25<>"",(proforma!D25),"")
B26: =IF(proforma!B26<>"",(proforma!B26),"") | C26: =IF(proforma!C26<>"",(proforma!C26),"") | D26: =IF(proforma!D26<>"",(proforma!D26),"")
B27: =IF(proforma!B27<>"",(proforma!B27),"") | C27: =IF(proforma!C27<>"",(proforma!C27),"") | D27: =IF(proforma!D27<>"",(proforma!D27),"")
B28: =IF(proforma!B28<>"",(proforma!B28),"") | C28: =IF(proforma!C28<>"",(proforma!C28),"") | D28: =IF(proforma!D28<>"",(proforma!D28),"")
B29: =IF(proforma!B29<>"",(proforma!B29),"") | C29: =IF(proforma!C29<>"",(proforma!C29),"") | D29: =IF(proforma!D29<>"",(proforma!D29),"")
B30: =IF(proforma!B30<>"",(proforma!B30),"") | C30: =IF(proforma!C30<>"",(proforma!C30),"") | D30: =IF(proforma!D30<>"",(proforma!D30),"")
... B40: =IF(proforma!B40<>"",(proforma!B40),"") | C40: =IF(proforma!C40<>"",(proforma!C40),"") | D40: =IF(proforma!D40<>"",(proforma!D40),"")
B41: =IF(proforma!B41<>"",(proforma!B41),"") | C41: =IF(proforma!C41<>"",(proforma!C41),"")
B42: =IF(proforma!B42<>"",(proforma!B42),"") -> SUB TOTAL BASE IMPONIBLE | C42: =IF(proforma!C42<>"",(proforma!C42),"")
B43: =IF(proforma!B43<>"",(proforma!B43),"") -> Descuento % | C43: =IF(proforma!C43<>"",(proforma!C43),"") -> ESPECIAL | D43: =IF(proforma!D41<>"",(proforma!D41),"")
B44: SUB TOTAL BASE IMPONIBLE
B45: =proforma!B43 -> Descuento %
B46: =IF(proforma!B44<>"",(proforma!B44),"") -> TOTAL BASE IMPONIBLE PINTURAS | D46: =IF(proforma!D44<>"",(proforma!D44),"")
B47: =IF(proforma!B45<>"",(proforma!B45),"") -> Portes Península
B48: =IF(proforma!B46<>"",(proforma!B46),"") -> MANO DE OBRA | D48: =IF(proforma!D46<>"",(proforma!D46),"")
B49: =IF(proforma!B47<>"",(proforma!B47),"") -> Otros Varios | D49: =IF(proforma!D47<>"",(proforma!D47),"")
B50: TOTAL BASE IMPONIBLE | D50: =IF(proforma!D48<>"",(proforma!D48),"")
B51: =IF(proforma!B49<>"",(proforma!B49),"") -> 21% IVA
B52: TOTAL FACTURA:
B55: Condiciones de Pago:
B57: Forma de Pago: | C57: =proforma!C55 -> Transferencia
...

Sheet factura
E4: FACTURA:
E5: Nº:
E6: =proforma!D6 -> FECHA:26/12/2025
E7: Según Proforma | F7: =proforma!D5 -> PROFORMA: 291225462RNM
B8: Datos del Cliente:
B9: Nombre: | C9: =IF(proforma!C9<>"",(proforma!C9),"") | D9: C.I.F: | E9: =IF(proforma!E9<>"",(proforma!E9),"")
B10: Dirección: | C10: =IF(proforma!C10<>"",(proforma!C10),"") | D10: C.P.: | E10: =IF(proforma!E10<>"",(proforma!E10),"")
B11: Ciudad: | C11: =IF(proforma!C11<>"",(proforma!C11),"") | D11: Provincia: | E11: =IF(proforma!E11<>"",(proforma!E11),"")
B12: Pais: | C12: =IF(proforma!C12<>"",(proforma!C12),"") | D12: Telf: | E12: =IF(proforma!E12<>"",(proforma!E12),"")
B13: Contacto: | C13: =IF(proforma!C13<>"",(proforma!C13),"") | D13: e -mail: | E13: =IF(proforma!E13<>"",(proforma!E13),"")
E14: =IF(proforma!E14<>"",(proforma!E14),"")
B15: Detalle de Conceptos:
B17: DENOMINACION | D17: Cant.Unit | E17: Precio €/U | F17: Total €
F18: =IF(D18<>"",D18*E18,"")
B19: =IF(proforma!B17<>"",(proforma!B17),"") -> DENOMINACION | C19: =IF(proforma!C17<>"",(proforma!C17),"")
B20: =IF(proforma!B19<>"",(proforma!B19),"") | C20: =IF(proforma!C19<>"",(proforma!C19),"") | E20: =IF(proforma!E19<>"",(proforma!E19),"")
B21: =IF(proforma!B20<>"",(proforma!B20),"") | C21: =IF(proforma!C20<>"",(proforma!C20),"") | D21: =IF(proforma!D20<>"",(proforma!D20),"") | E21: =IF(proforma!E20<>"",(proforma!E20),"") | F21: =IF(D21<>"",D21*E21,"")
B22: =IF(proforma!B21<>"",(proforma!B21),"") | C22: =IF(proforma!C21<>"",(proforma!C21),"") | D22: =IF(proforma!D21<>"",(proforma!D21),"") | E22: =IF(proforma!E21<>"",(proforma!E21),"") | F22: =IF(D22<>"",D22*E22,"")
B23: =IF(proforma!B22<>"",(proforma!B22),"") | C23: =IF(proforma!C22<>"",(proforma!C22),"") | D23: =IF(proforma!D22<>"",(proforma!D22),"") | E23: =IF(proforma!E22<>"",(proforma!E22),"") | F23: =IF(D23<>"",D23*E23,"")
B24: =IF(proforma!B23<>"",(proforma!B23),"") | C24: =IF(proforma!C23<>"",(proforma!C23),"") | D24: =IF(proforma!D23<>"",(proforma!D23),"") | E24: =IF(proforma!E23<>"",(proforma!E23),"") | F24: =IF(D24<>"",D24*E24,"")
B25: =IF(proforma!B24<>"",(proforma!B24),"") | C25: =IF(proforma!C24<>"",(proforma!C24),"") | D25: =IF(proforma!D24<>"",(proforma!D24),"") | E25: =IF(proforma!E24<>"",(proforma!E24),"") | F25: =IF(D25<>"",D25*E25,"")
B26: =IF(proforma!B25<>"",(proforma!B25),"") | C26: =IF(proforma!C25<>"",(proforma!C25),"") | D26: =IF(proforma!D25<>"",(proforma!D25),"") | E26: =IF(proforma!E25<>"",(proforma!E25),"") | F26: =IF(D26<>"",D26*E26,"")
B27: =IF(proforma!B26<>"",(proforma!B26),"") | C27: =IF(proforma!C26<>"",(proforma!C26),"") | D27: =IF(proforma!D26<>"",(proforma!D26),"") | E27: =IF(proforma!E26<>"",(proforma!E26),"") | F27: =IF(D27<>"",D27*E27,"")
B28: =IF(proforma!B27<>"",(proforma!B27),"") | C28: =IF(proforma!C27<>"",(proforma!C27),"") | D28: =IF(proforma!D27<>"",(proforma!D27),"") | E28: =IF(proforma!E27<>"",(proforma!E27),"") | F28: =IF(D28<>"",D28*E28,"")
B29: =IF(proforma!B28<>"",(proforma!B28),"") | C29: =IF(proforma!C28<>"",(proforma!C28),"") | D29: =IF(proforma!D28<>"",(proforma!D28),"") | E29: =IF(proforma!E28<>"",(proforma!E28),"") | F29: =IF(D29<>"",D29*E29,"")
B30: =IF(proforma!B29<>"",(proforma!B29),"") | C30: =IF(proforma!C29<>"",(proforma!C29),"") | D30: =IF(proforma!D29<>"",(proforma!D29),"") | E30: =IF(proforma!E29<>"",(proforma!E29),"") | F30: =IF(D30<>"",D30*E30,"")
B31: =IF(proforma!B30<>"",(proforma!B30),"") | C31: =IF(proforma!C30<>"",(proforma!C30),"") | D31: =IF(proforma!D30<>"",(proforma!D30),"") | E31: =IF(proforma!E30<>"",(proforma!E30),"") | F31: =IF(D31<>"",D31*E31,"")
B32: =IF(proforma!B31<>"",(proforma!B31),"") | C32: =IF(proforma!C31<>"",(proforma!C31),"") | D32: =IF(proforma!D31<>"",(proforma!D31),"") | E32: =IF(proforma!E31<>"",(proforma!E31),"") | F32: =IF(D32<>"",D32*E32,"")
... B42: =IF(proforma!B41<>"",(proforma!B41),"") | C42: =IF(proforma!C41<>"",(proforma!C41),"") | D42: =IF(proforma!D41<>"",(proforma!D41),"") | E42: =IF(proforma!E41<>"",(proforma!E41),"") | F42: =IF(D42<>"",D42*E42,"")
B43: SUB TOTAL BASE IMPONIBLE | F43: =SUM(F18:F42) -> 0
B44: =proforma!B43 -> Descuento % | D44: =proforma!D43 -> 50 | F44: =proforma!F43 -> 0
B45: =IF(proforma!B44<>"",(proforma!B44),"") -> TOTAL BASE IMPONIBLE PINTURAS | D45: =IF(proforma!D44<>"",(proforma!D44),"") | F45: =SUM(F43:F44) -> 0
B46: =IF(proforma!B45<>"",(proforma!B45),"") -> Portes Península | D46: =IF(proforma!D45<>"",(proforma!D45),"") -> 1 | F46: =proforma!F45 -> 17
B47: =IF(proforma!B46<>"",(proforma!B46),"") -> MANO DE OBRA | D47: =IF(proforma!D46<>"",(proforma!D46),"") | E47: =IF(proforma!E46<>"",(proforma!E46),"") | F47: =IF(D47<>"",(D47*E47),"")
B48: =IF(proforma!B47<>"",(proforma!B47),"") -> Otros Varios | D48: =IF(proforma!D47<>"",(proforma!D47),"") | E48: =IF(proforma!E47<>"",(proforma!E47),"") | F48: =IF(D48<>"",(D48*E48),"")
B49: =IF(proforma!B48<>"",(proforma!B48),"") -> TOTAL BASE IMPONIBLE | D49: =IF(proforma!D48<>"",(proforma!D48),"") | F49: =SUM(F45:F48) -> 17
B50: =IF(proforma!B49<>"",(proforma!B49),"") -> 21% IVA | F50: =IF(proforma!F49<>"",(proforma!F49),"") -> 3.57
B51: TOTAL FACTURA: | F51: =SUM(F49:F50) -> 20.57
B54: Condiciones de Pago:
B56: Forma de Pago: | C56: =proforma!C55 -> Transferencia
...

Sheet Hoja Entrega Transporte
E4: Factura:
E5: =factura!E5 -> Nº:
B6: Hoja de Entrega al Transportista: | E6: =factura!E6 -> FECHA:26/12/2025
B8: Entregamos al transportista : | C8: SCHENKER S.AU. | D8: de: | E8: ELDA(ALICANTE)
B9: la siguiente mercancia que abajo detallamos:
B11: Datos del Envio:
B13: Total de Bultos: | C13: =pedido!K17 -> 0
B14: Peso Neto(kg): | C14: =pedido!K15 -> 0
B15: Peso Bruto(Kg) | C15: =pedido!K16 -> 0
B16: Cubicaje (m3): | C16: =pedido!K18 -> 0
B17: Portes: | C17: =pedido!K19 -> PAGADOS
B19: Direccion de Envio:
B21: Nombre: | C21: =pedido!K9 | D21: C.I.F: | E21: =pedido!M9
B22: Dirección: | C22: =pedido!K10 | D22: C.P.: | E22: =pedido!M10
B23: Ciudad: | C23: =pedido!K11 | D23: Provincia: | E23: =IF(proforma!E11<>"",(proforma!E11),"")
B24: Pais: | C24: =pedido!K12 | D24: Telf: | E24: =pedido!M12
B25: Contacto: | C25: =pedido!K13 | D25: e -mail: | E25: =pedido!M13
B27: Observaciones:
B29: MERCANCIA NO SOMETIDA A LA CLASE 3
B30: Según marginal 2314 apartado 2 esta mercancía no esta sometida a la clase 3
B31: Mercancía clasificada como no peligrosa para el transporte por carretera
B39: NCHEMICALS PINTURAS Y RESINAS S.L. como propietario remitente de la mercancia CERTIFICA:
B40: * Que los porductos del presente envio se ajustan estrictamente a los datos aquí reseñados.
B41: * Que las mercancías se encuentran en perfecto estado en el momento de su carga.
B43: Conformidad Transportista: | C43: NCHEMICALS PINTURAS Y RESINAS S.L.
C44: Un gerente
B48: NCHEMICALS RESINAS Y PINTURAS S.L.U.
B49: C/ Cantueso 34 | E49: TF:+34 633 48 00 92
B50: 03600 ELDA (ALICANTE) – ESPAÑA
B51: C.I.F.: B16885279 | E51: E-mail: hola@nchemicals.es
E52: suelosderesina@gmail.com

Sheet Carta de Portes
E8: Carta de Porte
A9: Carta de Portes correspondiente a nuestra factura: | G9: =factura!E5 -> Nº:
G10: =factura!E6 -> FECHA:26/12/2025
A11: Destino: | F11: ='Hoja Entrega Transporte'!C23 | G11: ='Hoja Entrega Transporte'!E23
A12: Nombre del Transportista:
A13: Matriucla del Vehiculo:
A15: Tek Lacke Chemie,S.L. certifica que estas mercancías se admiten al transporte por carretera y que su estado,
A16: acondicionamiento y etiquetaje, están de acuerdo con las disposiciones del ADR/RD 2115/1998
A19: El Abajo firmante declara:
A21: 1.- Que el vehículo cargado cumple con las condiciones que establece el Reglamento
A22: Nacional para el Transporte de Mercancías Peligrosas por Carretera./
A24: 2.- Haberse realizado correctamente la carga y estiba de las mercancías.
A26: 3.- Haber recibido de NCHEMICALS PINTURAS Y RESINAS S.L., las hojas de instrucciones escritas respecto a:
B27: La naturaleza y peligro de las mercancías a transportar.
B28: Las medidas a adoptar en caso de accidente, incendio o rotura de envases,
B29: todas las cuales conozco.
A30: 4.- Conocer las disposiciones generales y especiales sobre vehículos; carga, descarga
A31: , manipulación y circulación de las mercancías que establece el citado Reglamento.
A35: Firma del Transportista: | F35: Firma del Expedidor:
A38: Nombre
A39: DNI:
A43: Relación de mercancías transportadas y clasificadas según ADR
A44: Mercancias | C44: NºOnu | E44: Clasificación
A45: Pinturas | C45: UN 1263 | E45: MERCANCIA NO SOMETIDA A LA CLASE 3
E46: seguna marginal 2314 apartado 2 esta mercancia no está sometida a la clase 3
E47: Mercancia clasificada como no èligrosa para el transporte por carretera

Sheet etiquetas envio
B2: Datos del Cliente:
B3: Nombre: | C3: =pedido!K9 | D3: C.I.F: | E3: =pedido!M9
B4: Dirección: | C4: =pedido!K10 | D4: C.P.: | E4: =pedido!M10
B5: Ciudad: | C5: =pedido!K11 | D5: Provincia: | E5: =pedido!M11
B6: Pais: | C6: =pedido!K12 | D6: Telf: | E6: =pedido!M12
B7: Contacto: | C7: =pedido!K13 | D7: e -mail: | E7: =pedido!M13
B9: Factura: | C9: =factura!E5 -> Nº: | D9: =factura!E6 -> FECHA:26/12/2025
B11: Nº DE BULTOS: | C11: ='Hoja Entrega Transporte'!C13 -> 0 | D11: BULTOS Nº:
B13: PESO NETO(Kg): | C13: ='Hoja Entrega Transporte'!C14 -> 0 | D13: PESO BRUTO(Kg): | E13: ='Hoja Entrega Transporte'!C15 -> 0
